<?xml version="1.0" encoding="utf-8"?>
<!-- This URDF was automatically created by SolidWorks to URDF Exporter! Originally created by Stephen Brawner (brawner@gmail.com) 
     Commit Version: 1.5.1-0-g916b5db  Build Version: 1.5.7152.31018
     For more information, please see http://wiki.ros.org/sw_urdf_exporter -->
<robot
  name="seeding_robot">
 <link name="world" />
  <joint name="virtual_joint" type="fixed">
      <parent link="world" />
      <child link="base_link" />
      <origin xyz="0.0 0.0 0.0" rpy="0.0 0.0 0.0" />
  </joint>
  <link
    name="base_link">
    <inertial>
      <origin
        xyz="-0.091014 0.38141 0.27766"
        rpy="0 0 0" />
      <mass
        value="9.0203" />
      <inertia
        ixx="0.20485"
        ixy="-0.12697"
        ixz="8.6668E-18"
        iyy="0.60618"
        iyz="-1.9062E-17"
        izz="0.67866" />
    </inertial>
    <visual>
      <origin
        xyz="0 0 0"
        rpy="0 0 0" />
      <geometry>
        <mesh
          filename="package://seeding_robot/meshes/base_link.STL" />
      </geometry>
      <material
        name="">
        <color
          rgba="0.79216 0.81961 0.93333 1" />
      </material>
    </visual>
    <collision>
      <origin
        xyz="0 0 0"
        rpy="0 0 0" />
      <geometry>
        <mesh
          filename="package://seeding_robot/meshes/base_link.STL" />
      </geometry>
    </collision>
  </link>
  <link
    name="Arm1_Link">
    <inertial>
      <origin
        xyz="5.5511E-17 0.096893 0"
        rpy="0 0 0" />
      <mass
        value="0.47625" />
      <inertia
        ixx="0.0020184"
        ixy="-2.0494E-18"
        ixz="2.0329E-20"
        iyy="0.00032396"
        iyz="1.3325E-20"
        izz="0.0020184" />
    </inertial>
    <visual>
      <origin
        xyz="0 0 0"
        rpy="0 0 0" />
      <geometry>
        <mesh
          filename="package://seeding_robot/meshes/Arm1_Link.STL" />
      </geometry>
      <material
        name="">
        <color
          rgba="0.79216 0.81961 0.93333 1" />
      </material>
    </visual>
    <collision>
      <origin
        xyz="0 0 0"
        rpy="0 0 0" />
      <geometry>
        <mesh
          filename="package://seeding_robot/meshes/Arm1_Link.STL" />
      </geometry>
    </collision>
  </link>
  <joint
    name="Arm1"
    type="continuous">
    <origin
      xyz="0.36583 -0.27766 0.27174"
      rpy="1.5708 0 -1.5458" />
    <parent
      link="base_link" />
    <child
      link="Arm1_Link" />
    <axis
      xyz="0 1 0" />
  </joint>
  <link
    name="Arm11_Link">
    <inertial>
      <origin
        xyz="-9.992E-16 -0.0024163 0.01573"
        rpy="0 0 0" />
      <mass
        value="0.2748" />
      <inertia
        ixx="0.0010682"
        ixy="-5.5904E-20"
        ixz="-5.8445E-19"
        iyy="0.00030291"
        iyz="0.00011923"
        izz="0.00095068" />
    </inertial>
    <visual>
      <origin
        xyz="0 0 0"
        rpy="0 0 0" />
      <geometry>
        <mesh
          filename="package://seeding_robot/meshes/Arm11_Link.STL" />
      </geometry>
      <material
        name="">
        <color
          rgba="0.79216 0.81961 0.93333 1" />
      </material>
    </visual>
    <collision>
      <origin
        xyz="0 0 0"
        rpy="0 0 0" />
      <geometry>
        <mesh
          filename="package://seeding_robot/meshes/Arm11_Link.STL" />
      </geometry>
    </collision>
  </link>
  <joint
    name="Arm11"
    type="prismatic">
    <origin
      xyz="0 0 0"
      rpy="0 0 0" />
    <parent
      link="Arm1_Link" />
    <child
      link="Arm11_Link" />
    <axis
      xyz="0 1 0" />
    <limit
      lower="-0.089"
      upper="0"
      effort="0"
      velocity="100" />
  </joint>
  <link
    name="Arm12_Link">
    <inertial>
      <origin
        xyz="-0.051502 -0.0077993 -1.6653E-16"
        rpy="0 0 0" />
      <mass
        value="0.0774" />
      <inertia
        ixx="8.3192E-05"
        ixy="-5.5432E-05"
        ixz="-1.2695E-18"
        iyy="0.00041495"
        iyz="-3.1446E-19"
        izz="0.00036449" />
    </inertial>
    <visual>
      <origin
        xyz="0 0 0"
        rpy="0 0 0" />
      <geometry>
        <mesh
          filename="package://seeding_robot/meshes/Arm12_Link.STL" />
      </geometry>
      <material
        name="">
        <color
          rgba="0.79216 0.81961 0.93333 1" />
      </material>
    </visual>
    <collision>
      <origin
        xyz="0 0 0"
        rpy="0 0 0" />
      <geometry>
        <mesh
          filename="package://seeding_robot/meshes/Arm12_Link.STL" />
      </geometry>
    </collision>
  </link>
  <joint
    name="Arm12"
    type="prismatic">
    <origin
      xyz="0 -0.03 0"
      rpy="0 1.5708 0" />
    <parent
      link="Arm11_Link" />
    <child
      link="Arm12_Link" />
    <axis
      xyz="1 0 0" />
    <limit
      lower="-0.087645"
      upper="0.0023551"
      effort="0"
      velocity="100" />
  </joint>
  <link
    name="Arm2_Link">
    <inertial>
      <origin
        xyz="0.02011 0.031623 -1.6982E-09"
        rpy="0 0 0" />
      <mass
        value="0.23479" />
      <inertia
        ixx="0.00019009"
        ixy="-2.0666E-05"
        ixz="7.7886E-12"
        iyy="0.00064151"
        iyz="1.4664E-12"
        izz="0.00059667" />
    </inertial>
    <visual>
      <origin
        xyz="0 0 0"
        rpy="0 0 0" />
      <geometry>
        <mesh
          filename="package://seeding_robot/meshes/Arm2_Link.STL" />
      </geometry>
      <material
        name="">
        <color
          rgba="0.79216 0.81961 0.93333 1" />
      </material>
    </visual>
    <collision>
      <origin
        xyz="0 0 0"
        rpy="0 0 0" />
      <geometry>
        <mesh
          filename="package://seeding_robot/meshes/Arm2_Link.STL" />
      </geometry>
    </collision>
  </link>
  <joint
    name="Arm2"
    type="continuous">
    <origin
      xyz="-0.14417 -0.27766 0.21274"
      rpy="1.5708 0 0.0138" />
    <parent
      link="base_link" />
    <child
      link="Arm2_Link" />
    <axis
      xyz="0 1 0" />
  </joint>
  <link
    name="Arm21_Link">
    <inertial>
      <origin
        xyz="0.055657 0 0.0031343"
        rpy="0 0 0" />
      <mass
        value="0.067" />
      <inertia
        ixx="2.1178E-05"
        ixy="-4.9892E-21"
        ixz="-1.1827E-05"
        iyy="0.00012999"
        iyz="-1.0094E-21"
        izz="0.00011614" />
    </inertial>
    <visual>
      <origin
        xyz="0 0 0"
        rpy="0 0 0" />
      <geometry>
        <mesh
          filename="package://seeding_robot/meshes/Arm21_Link.STL" />
      </geometry>
      <material
        name="">
        <color
          rgba="0.79216 0.81961 0.93333 1" />
      </material>
    </visual>
    <collision>
      <origin
        xyz="0 0 0"
        rpy="0 0 0" />
      <geometry>
        <mesh
          filename="package://seeding_robot/meshes/Arm21_Link.STL" />
      </geometry>
    </collision>
  </link>
  <joint
    name="Arm21"
    type="prismatic">
    <origin
      xyz="0.051904 0.036 0"
      rpy="0 0 0" />
    <parent
      link="Arm2_Link" />
    <child
      link="Arm21_Link" />
    <axis
      xyz="1 0 0" />
    <limit
      lower="0.0008805"
      upper="0.089119"
      effort="0"
      velocity="100" />
  </joint>
  <link
    name="Arm22move_Link">
    <inertial>
      <origin
        xyz="0.010249 4.5103E-17 0.016091"
        rpy="0 0 0" />
      <mass
        value="0.005116" />
      <inertia
        ixx="4.273E-07"
        ixy="7.486E-23"
        ixz="2.0475E-07"
        iyy="1.1952E-06"
        iyz="2.5643E-22"
        izz="1.2921E-06" />
    </inertial>
    <visual>
      <origin
        xyz="0 0 0"
        rpy="0 0 0" />
      <geometry>
        <mesh
          filename="package://seeding_robot/meshes/Arm22move_Link.STL" />
      </geometry>
      <material
        name="">
        <color
          rgba="0.79216 0.81961 0.93333 1" />
      </material>
    </visual>
    <collision>
      <origin
        xyz="0 0 0"
        rpy="0 0 0" />
      <geometry>
        <mesh
          filename="package://seeding_robot/meshes/Arm22move_Link.STL" />
      </geometry>
    </collision>
  </link>
  <joint
    name="Arm22move"
    type="prismatic">
    <origin
      xyz="0.11198 0 0.013951"
      rpy="0 0 -1.5708" />
    <parent
      link="Arm21_Link" />
    <child
      link="Arm22move_Link" />
    <axis
      xyz="0 0 1" />
    <limit
      lower="-0.022755"
      upper="0.007245"
      effort="0"
      velocity="100" />
  </joint>
  <link
    name="Arm22fix_Link">
    <inertial>
      <origin
        xyz="0.0095444 -3.4694E-18 -0.0024236"
        rpy="0 0 0" />
      <mass
        value="0.004889" />
      <inertia
        ixx="3.7891E-07"
        ixy="-1.034E-23"
        ixz="-1.9468E-07"
        iyy="1.0931E-06"
        iyz="-7.7755E-23"
        izz="1.1652E-06" />
    </inertial>
    <visual>
      <origin
        xyz="0 0 0"
        rpy="0 0 0" />
      <geometry>
        <mesh
          filename="package://seeding_robot/meshes/Arm22fix_Link.STL" />
      </geometry>
      <material
        name="">
        <color
          rgba="0.79216 0.81961 0.93333 1" />
      </material>
    </visual>
    <collision>
      <origin
        xyz="0 0 0"
        rpy="0 0 0" />
      <geometry>
        <mesh
          filename="package://seeding_robot/meshes/Arm22fix_Link.STL" />
      </geometry>
    </collision>
  </link>
  <joint
    name="Arm22fix"
    type="fixed">
    <origin
      xyz="0.11198 0 -0.005"
      rpy="0 0 -1.5708" />
    <parent
      link="Arm21_Link" />
    <child
      link="Arm22fix_Link" />
    <axis
      xyz="0 0 0" />
  </joint>
  <link
    name="Rollerstick_Link">
    <inertial>
      <origin
        xyz="0 0 0"
        rpy="0 0 0" />
      <mass
        value="0" />
      <inertia
        ixx="0"
        ixy="0"
        ixz="0"
        iyy="0"
        iyz="0"
        izz="0" />
    </inertial>
    <visual>
      <origin
        xyz="0 0 0"
        rpy="0 0 0" />
      <geometry>
        <mesh
          filename="package://seeding_robot/meshes/Rollerstick_Link.STL" />
      </geometry>
      <material
        name="">
        <color
          rgba="1 1 1 1" />
      </material>
    </visual>
    <collision>
      <origin
        xyz="0 0 0"
        rpy="0 0 0" />
      <geometry>
        <mesh
          filename="package://seeding_robot/meshes/Rollerstick_Link.STL" />
      </geometry>
    </collision>
  </link>
  <joint
    name="Rollerstick"
    type="fixed">
    <origin
      xyz="-0.33417 -0.38766 0.13274"
      rpy="1.5708 0 1.5144" />
    <parent
      link="base_link" />
    <child
      link="Rollerstick_Link" />
    <axis
      xyz="0 1 0" />
  </joint>
  <link
    name="Roller_Link">
    <inertial>
      <origin
        xyz="-0.10985 0.1197 0.072832"
        rpy="0 0 0" />
      <mass
        value="0.14137" />
      <inertia
        ixx="3.003E-05"
        ixy="-2.0887E-07"
        ixz="-1.2709E-07"
        iyy="1.7679E-05"
        iyz="4.8879E-09"
        izz="1.7674E-05" />
    </inertial>
    <visual>
      <origin
        xyz="0 0 0"
        rpy="0 0 0" />
      <geometry>
        <mesh
          filename="package://seeding_robot/meshes/Roller_Link.STL" />
      </geometry>
      <material
        name="">
        <color
          rgba="0.79216 0.81961 0.93333 1" />
      </material>
    </visual>
    <collision>
      <origin
        xyz="0 0 0"
        rpy="0 0 0" />
      <geometry>
        <mesh
          filename="package://seeding_robot/meshes/Roller_Link.STL" />
      </geometry>
    </collision>
  </link>
  <joint
    name="Roller"
    type="fixed">
    <origin
      xyz="0 0.01 0"
      rpy="1.0242 -0.057409 -3.1416" />
    <parent
      link="Rollerstick_Link" />
    <child
      link="Roller_Link" />
    <axis
      xyz="1 0 0" />
  </joint>
<transmission name="trans_Arm1">
        <type>transmission_interface/SimpleTransmission</type>
        <joint name="Arm1">
            <hardwareInterface>hardware_interface/PositionJointInterface</hardwareInterface>
        </joint>
        <actuator name="Arm1_motor">
            <hardwareInterface>hardware_interface/PositionJointInterface</hardwareInterface>
            <mechanicalReduction>1</mechanicalReduction>
        </actuator>
    </transmission>
    <transmission name="trans_Arm11">
        <type>transmission_interface/SimpleTransmission</type>
        <joint name="Arm11">
            <hardwareInterface>hardware_interface/PositionJointInterface</hardwareInterface>
        </joint>
        <actuator name="Arm11_motor">
            <hardwareInterface>hardware_interface/PositionJointInterface</hardwareInterface>
            <mechanicalReduction>1</mechanicalReduction>
        </actuator>
    </transmission>
    <transmission name="trans_Arm12">
        <type>transmission_interface/SimpleTransmission</type>
        <joint name="Arm12">
            <hardwareInterface>hardware_interface/PositionJointInterface</hardwareInterface>
        </joint>
        <actuator name="Arm12_motor">
            <hardwareInterface>hardware_interface/PositionJointInterface</hardwareInterface>
            <mechanicalReduction>1</mechanicalReduction>
        </actuator>
    </transmission>
    <transmission name="trans_Arm2">
        <type>transmission_interface/SimpleTransmission</type>
        <joint name="Arm2">
            <hardwareInterface>hardware_interface/PositionJointInterface</hardwareInterface>
        </joint>
        <actuator name="Arm2_motor">
            <hardwareInterface>hardware_interface/PositionJointInterface</hardwareInterface>
            <mechanicalReduction>1</mechanicalReduction>
        </actuator>
    </transmission>
    <transmission name="trans_Arm21">
        <type>transmission_interface/SimpleTransmission</type>
        <joint name="Arm21">
            <hardwareInterface>hardware_interface/PositionJointInterface</hardwareInterface>
        </joint>
        <actuator name="Arm21_motor">
            <hardwareInterface>hardware_interface/PositionJointInterface</hardwareInterface>
            <mechanicalReduction>1</mechanicalReduction>
        </actuator>
    </transmission>
    <transmission name="trans_Arm22move">
        <type>transmission_interface/SimpleTransmission</type>
        <joint name="Arm22move">
            <hardwareInterface>hardware_interface/PositionJointInterface</hardwareInterface>
        </joint>
        <actuator name="Arm22move_motor">
            <hardwareInterface>hardware_interface/PositionJointInterface</hardwareInterface>
            <mechanicalReduction>1</mechanicalReduction>
        </actuator>
    </transmission>
    <gazebo>
        <plugin name="gazebo_ros_control" filename="libgazebo_ros_control.so">
            <robotNamespace>/</robotNamespace>
        </plugin>
    </gazebo>
</robot>
